Workbook

Sheet Movimenti
A1: data | B1: causale | C1: entrate (USD) | D1: uscite (USD) | E1: saldo (USD) | F1: cambio | G1: data cambio usata | H1: entrate (EUR) | I1: uscite (EUR) | J1: saldo (EUR) | K1: gg | L1: saldo x gg (EUR)
A2: 45657 | B2: saldo 1.1.2025 | C2: 1605.36 | E2: =N(C2)-N(D2) | F2: ='Medie mensili'!C2 | G2: media mensile | H2: =IF(C2="","",C2/F2) | I2: =IF(D2="","",D2/F2) | J2: =N(H2)-N(I2) | K2: =A3-A2 | L2: =K2*J2
A3: 45666 | C3: 1000 | E3: =E2+N(C3)-N(D3) | F3: =LOOKUP(A3,Cambi!$A$2:$A$255,Cambi!$B$2:$B$255) | G3: =LOOKUP(A3,Cambi!$A$2:$A$255,Cambi!$A$2:$A$255) | H3: =IF(C3="","",C3/F3) | I3: =IF(D3="","",D3/F3) | J3: =J2+N(H3)-N(I3) | K3: =A4-A3 | L3: =K3*J3
A4: 45666 | C4: 2500 | E4: =E3+N(C4)-N(D4) | F4: =LOOKUP(A4,Cambi!$A$2:$A$255,Cambi!$B$2:$B$255) | G4: =LOOKUP(A4,Cambi!$A$2:$A$255,Cambi!$A$2:$A$255) | H4: =IF(C4="","",C4/F4) | I4: =IF(D4="","",D4/F4) | J4: =J3+N(H4)-N(I4) | K4: =A5-A4 | L4: =K4*J4
A5: 45670 | D5: 3000 | E5: =E4+N(C5)-N(D5) | F5: =LOOKUP(A5,Cambi!$A$2:$A$255,Cambi!$B$2:$B$255) | G5: =LOOKUP(A5,Cambi!$A$2:$A$255,Cambi!$A$2:$A$255) | H5: =IF(C5="","",C5/F5) | I5: =IF(D5="","",D5/F5) | J5: =J4+N(H5)-N(I5) | K5: =A6-A5 | L5: =K5*J5
A6: 45677 | C6: 600 | E6: =E5+N(C6)-N(D6) | F6: =LOOKUP(A6,Cambi!$A$2:$A$255,Cambi!$B$2:$B$255) | G6: =LOOKUP(A6,Cambi!$A$2:$A$255,Cambi!$A$2:$A$255) | H6: =IF(C6="","",C6/F6) | I6: =IF(D6="","",D6/F6) | J6: =J5+N(H6)-N(I6) | K6: =A7-A6 | L6: =K6*J6
A7: 45681 | C7: 14824.2 | E7: =E6+N(C7)-N(D7) | F7: =LOOKUP(A7,Cambi!$A$2:$A$255,Cambi!$B$2:$B$255) | G7: =LOOKUP(A7,Cambi!$A$2:$A$255,Cambi!$A$2:$A$255) | H7: =IF(C7="","",C7/F7) | I7: =IF(D7="","",D7/F7) | J7: =J6+N(H7)-N(I7) | K7: =A8-A7 | L7: =K7*J7
A8: 45681 | D8: 14824.2 | E8: =E7+N(C8)-N(D8) | F8: =LOOKUP(A8,Cambi!$A$2:$A$255,Cambi!$B$2:$B$255) | G8: =LOOKUP(A8,Cambi!$A$2:$A$255,Cambi!$A$2:$A$255) | H8: =IF(C8="","",C8/F8) | I8: =IF(D8="","",D8/F8) | J8: =J7+N(H8)-N(I8) | K8: =A9-A8 | L8: =K8*J8
A9: 45691 | D9: 1276 | E9: =E8+N(C9)-N(D9) | F9: =LOOKUP(A9,Cambi!$A$2:$A$255,Cambi!$B$2:$B$255) | G9: =LOOKUP(A9,Cambi!$A$2:$A$255,Cambi!$A$2:$A$255) | H9: =IF(C9="","",C9/F9) | I9: =IF(D9="","",D9/F9) | J9: =J8+N(H9)-N(I9) | K9: =A10-A9 | L9: =K9*J9
A10: 45691 | C10: 1000 | E10: =E9+N(C10)-N(D10) | F10: =LOOKUP(A10,Cambi!$A$2:$A$255,Cambi!$B$2:$B$255) | G10: =LOOKUP(A10,Cambi!$A$2:$A$255,Cambi!$A$2:$A$255) | H10: =IF(C10="","",C10/F10) | I10: =IF(D10="","",D10/F10) | J10: =J9+N(H10)-N(I10) | K10: =A11-A10 | L10: =K10*J10
A11: 45698 | C11: 1000 | E11: =E10+N(C11)-N(D11) | F11: =LOOKUP(A11,Cambi!$A$2:$A$255,Cambi!$B$2:$B$255) | G11: =LOOKUP(A11,Cambi!$A$2:$A$255,Cambi!$A$2:$A$255) | H11: =IF(C11="","",C11/F11) | I11: =IF(D11="","",D11/F11) | J11: =J10+N(H11)-N(I11) | K11: =A12-A11 | L11: =K11*J11
A12: 45705 | D12: 700 | E12: =E11+N(C12)-N(D12) | F12: =LOOKUP(A12,Cambi!$A$2:$A$255,Cambi!$B$2:$B$255) | G12: =LOOKUP(A12,Cambi!$A$2:$A$255,Cambi!$A$2:$A$255) | H12: =IF(C12="","",C12/F12) | I12: =IF(D12="","",D12/F12) | J12: =J11+N(H12)-N(I12) | K12: =A13-A12 | L12: =K12*J12
A13: 45713 | C13: 600 | E13: =E12+N(C13)-N(D13) | F13: =LOOKUP(A13,Cambi!$A$2:$A$255,Cambi!$B$2:$B$255) | G13: =LOOKUP(A13,Cambi!$A$2:$A$255,Cambi!$A$2:$A$255) | H13: =IF(C13="","",C13/F13) | I13: =IF(D13="","",D13/F13) | J13: =J12+N(H13)-N(I13) | K13: =A14-A13 | L13: =K13*J13
A14: 45716 | C14: 2000 | E14: =E13+N(C14)-N(D14) | F14: =LOOKUP(A14,Cambi!$A$2:$A$255,Cambi!$B$2:$B$255) | G14: =LOOKUP(A14,Cambi!$A$2:$A$255,Cambi!$A$2:$A$255) | H14: =IF(C14="","",C14/F14) | I14: =IF(D14="","",D14/F14) | J14: =J13+N(H14)-N(I14) | K14: =A15-A14 | L14: =K14*J14
A15: 45716 | D15: 3510.77 | E15: =E14+N(C15)-N(D15) | F15: =LOOKUP(A15,Cambi!$A$2:$A$255,Cambi!$B$2:$B$255) | G15: =LOOKUP(A15,Cambi!$A$2:$A$255,Cambi!$A$2:$A$255) | H15: =IF(C15="","",C15/F15) | I15: =IF(D15="","",D15/F15) | J15: =J14+N(H15)-N(I15) | K15: =A16-A15 | L15: =K15*J15
A16: 45721 | D16: 597.6 | E16: =E15+N(C16)-N(D16) | F16: =LOOKUP(A16,Cambi!$A$2:$A$255,Cambi!$B$2:$B$255) | G16: =LOOKUP(A16,Cambi!$A$2:$A$255,Cambi!$A$2:$A$255) | H16: =IF(C16="","",C16/F16) | I16: =IF(D16="","",D16/F16) | J16: =J15+N(H16)-N(I16) | K16: =A17-A16 | L16: =K16*J16
A17: 45727 | C17: 1000 | E17: =E16+N(C17)-N(D17) | F17: =LOOKUP(A17,Cambi!$A$2:$A$255,Cambi!$B$2:$B$255) | G17: =LOOKUP(A17,Cambi!$A$2:$A$255,Cambi!$A$2:$A$255) | H17: =IF(C17="","",C17/F17) | I17: =IF(D17="","",D17/F17) | J17: =J16+N(H17)-N(I17) | K17: =A18-A17 | L17: =K17*J17
A18: 45736 | C18: 600 | E18: =E17+N(C18)-N(D18) | F18: =LOOKUP(A18,Cambi!$A$2:$A$255,Cambi!$B$2:$B$255) | G18: =LOOKUP(A18,Cambi!$A$2:$A$255,Cambi!$A$2:$A$255) | H18: =IF(C18="","",C18/F18) | I18: =IF(D18="","",D18/F18) | J18: =J17+N(H18)-N(I18) | K18: =A19-A18 | L18: =K18*J18
A19: 45756 | C19: 1000 | E19: =E18+N(C19)-N(D19) | F19: =LOOKUP(A19,Cambi!$A$2:$A$255,Cambi!$B$2:$B$255) | G19: =LOOKUP(A19,Cambi!$A$2:$A$255,Cambi!$A$2:$A$255) | H19: =IF(C19="","",C19/F19) | I19: =IF(D19="","",D19/F19) | J19: =J18+N(H19)-N(I19) | K19: =A20-A19 | L19: =K19*J19
A20: 45767 | C20: 600 | E20: =E19+N(C20)-N(D20) | F20: =LOOKUP(A20,Cambi!$A$2:$A$255,Cambi!$B$2:$B$255) | G20: =LOOKUP(A20,Cambi!$A$2:$A$255,Cambi!$A$2:$A$255) | H20: =IF(C20="","",C20/F20) | I20: =IF(D20="","",D20/F20) | J20: =J19+N(H20)-N(I20) | K20: =A21-A20 | L20: =K20*J20
A21: 45780 | C21: 10000 | E21: =E20+N(C21)-N(D21) | F21: =LOOKUP(A21,Cambi!$A$2:$A$255,Cambi!$B$2:$B$255) | G21: =LOOKUP(A21,Cambi!$A$2:$A$255,Cambi!$A$2:$A$255) | H21: =IF(C21="","",C21/F21) | I21: =IF(D21="","",D21/F21) | J21: =J20+N(H21)-N(I21) | K21: =A22-A21 | L21: =K21*J21
A22: 45780 | D22: 11976 | E22: =E21+N(C22)-N(D22) | F22: =LOOKUP(A22,Cambi!$A$2:$A$255,Cambi!$B$2:$B$255) | G22: =LOOKUP(A22,Cambi!$A$2:$A$255,Cambi!$A$2:$A$255) | H22: =IF(C22="","",C22/F22) | I22: =IF(D22="","",D22/F22) | J22: =J21+N(H22)-N(I22) | K22: =A23-A22 | L22: =K22*J22
A23: 45786 | C23: 1000 | E23: =E22+N(C23)-N(D23) | F23: =LOOKUP(A23,Cambi!$A$2:$A$255,Cambi!$B$2:$B$255) | G23: =LOOKUP(A23,Cambi!$A$2:$A$255,Cambi!$A$2:$A$255) | H23: =IF(C23="","",C23/F23) | I23: =IF(D23="","",D23/F23) | J23: =J22+N(H23)-N(I23) | K23: =A24-A23 | L23: =K23*J23
A24: 45797 | C24: 600 | E24: =E23+N(C24)-N(D24) | F24: =LOOKUP(A24,Cambi!$A$2:$A$255,Cambi!$B$2:$B$255) | G24: =LOOKUP(A24,Cambi!$A$2:$A$255,Cambi!$A$2:$A$255) | H24: =IF(C24="","",C24/F24) | I24: =IF(D24="","",D24/F24) | J24: =J23+N(H24)-N(I24) | K24: =A25-A24 | L24: =K24*J24
A25: 45812 | C25: 1000 | E25: =E24+N(C25)-N(D25) | F25: =LOOKUP(A25,Cambi!$A$2:$A$255,Cambi!$B$2:$B$255) | G25: =LOOKUP(A25,Cambi!$A$2:$A$255,Cambi!$A$2:$A$255) | H25: =IF(C25="","",C25/F25) | I25: =IF(D25="","",D25/F25) | J25: =J24+N(H25)-N(I25) | K25: =A26-A25 | L25: =K25*J25
A26: 45829 | C26: 600 | E26: =E25+N(C26)-N(D26) | F26: =LOOKUP(A26,Cambi!$A$2:$A$255,Cambi!$B$2:$B$255) | G26: =LOOKUP(A26,Cambi!$A$2:$A$255,Cambi!$A$2:$A$255) | H26: =IF(C26="","",C26/F26) | I26: =IF(D26="","",D26/F26) | J26: =J25+N(H26)-N(I26) | K26: =A27-A26 | L26: =K26*J26
A27: 45840 | D27: 3000 | E27: =E26+N(C27)-N(D27) | F27: =LOOKUP(A27,Cambi!$A$2:$A$255,Cambi!$B$2:$B$255) | G27: =LOOKUP(A27,Cambi!$A$2:$A$255,Cambi!$A$2:$A$255) | H27: =IF(C27="","",C27/F27) | I27: =IF(D27="","",D27/F27) | J27: =J26+N(H27)-N(I27) | K27: =A28-A27 | L27: =K27*J27
A28: 45840 | D28: 1480 | E28: =E27+N(C28)-N(D28) | F28: =LOOKUP(A28,Cambi!$A$2:$A$255,Cambi!$B$2:$B$255) | G28: =LOOKUP(A28,Cambi!$A$2:$A$255,Cambi!$A$2:$A$255) | H28: =IF(C28="","",C28/F28) | I28: =IF(D28="","",D28/F28) | J28: =J27+N(H28)-N(I28) | K28: =A29-A28 | L28: =K28*J28
A29: 45861 | C29: 600 | E29: =E28+N(C29)-N(D29) | F29: =LOOKUP(A29,Cambi!$A$2:$A$255,Cambi!$B$2:$B$255) | G29: =LOOKUP(A29,Cambi!$A$2:$A$255,Cambi!$A$2:$A$255) | H29: =IF(C29="","",C29/F29) | I29: =IF(D29="","",D29/F29) | J29: =J28+N(H29)-N(I29) | K29: =A30-A29 | L29: =K29*J29
A30: 45863 | C30: 4000 | E30: =E29+N(C30)-N(D30) | F30: =LOOKUP(A30,Cambi!$A$2:$A$255,Cambi!$B$2:$B$255) | G30: =LOOKUP(A30,Cambi!$A$2:$A$255,Cambi!$A$2:$A$255) | H30: =IF(C30="","",C30/F30) | I30: =IF(D30="","",D30/F30) | J30: =J29+N(H30)-N(I30) | K30: =A31-A30 | L30: =K30*J30
A31: 45863 | D31: 4941.4 | E31: =E30+N(C31)-N(D31) | F31: =LOOKUP(A31,Cambi!$A$2:$A$255,Cambi!$B$2:$B$255) | G31: =LOOKUP(A31,Cambi!$A$2:$A$255,Cambi!$A$2:$A$255) | H31: =IF(C31="","",C31/F31) | I31: =IF(D31="","",D31/F31) | J31: =J30+N(H31)-N(I31) | K31: =A32-A31 | L31: =K31*J31
A32: 45876 | C32: 1000 | E32: =E31+N(C32)-N(D32) | F32: =LOOKUP(A32,Cambi!$A$2:$A$255,Cambi!$B$2:$B$255) | G32: =LOOKUP(A32,Cambi!$A$2:$A$255,Cambi!$A$2:$A$255) | H32: =IF(C32="","",C32/F32) | I32: =IF(D32="","",D32/F32) | J32: =J31+N(H32)-N(I32) | K32: =A33-A32 | L32: =K32*J32
A33: 45888 | D33: 180 | E33: =E32+N(C33)-N(D33) | F33: =LOOKUP(A33,Cambi!$A$2:$A$255,Cambi!$B$2:$B$255) | G33: =LOOKUP(A33,Cambi!$A$2:$A$255,Cambi!$A$2:$A$255) | H33: =IF(C33="","",C33/F33) | I33: =IF(D33="","",D33/F33) | J33: =J32+N(H33)-N(I33) | K33: =A34-A33 | L33: =K33*J33
A34: 45889 | C34: 600 | E34: =E33+N(C34)-N(D34) | F34: =LOOKUP(A34,Cambi!$A$2:$A$255,Cambi!$B$2:$B$255) | G34: =LOOKUP(A34,Cambi!$A$2:$A$255,Cambi!$A$2:$A$255) | H34: =IF(C34="","",C34/F34) | I34: =IF(D34="","",D34/F34) | J34: =J33+N(H34)-N(I34) | K34: =A35-A34 | L34: =K34*J34
A35: 45905 | C35: 1000 | E35: =E34+N(C35)-N(D35) | F35: =LOOKUP(A35,Cambi!$A$2:$A$255,Cambi!$B$2:$B$255) | G35: =LOOKUP(A35,Cambi!$A$2:$A$255,Cambi!$A$2:$A$255) | H35: =IF(C35="","",C35/F35) | I35: =IF(D35="","",D35/F35) | J35: =J34+N(H35)-N(I35) | K35: =A36-A35 | L35: =K35*J35
A36: 45920 | C36: 600 | E36: =E35+N(C36)-N(D36) | F36: =LOOKUP(A36,Cambi!$A$2:$A$255,Cambi!$B$2:$B$255) | G36: =LOOKUP(A36,Cambi!$A$2:$A$255,Cambi!$A$2:$A$255) | H36: =IF(C36="","",C36/F36) | I36: =IF(D36="","",D36/F36) | J36: =J35+N(H36)-N(I36) | K36: =A37-A36 | L36: =K36*J36
A37: 45927 | D37: 2000 | E37: =E36+N(C37)-N(D37) | F37: =LOOKUP(A37,Cambi!$A$2:$A$255,Cambi!$B$2:$B$255) | G37: =LOOKUP(A37,Cambi!$A$2:$A$255,Cambi!$A$2:$A$255) | H37: =IF(C37="","",C37/F37) | I37: =IF(D37="","",D37/F37) | J37: =J36+N(H37)-N(I37) | K37: =A38-A37 | L37: =K37*J37
A38: 45940 | C38: 1000 | E38: =E37+N(C38)-N(D38) | F38: =LOOKUP(A38,Cambi!$A$2:$A$255,Cambi!$B$2:$B$255) | G38: =LOOKUP(A38,Cambi!$A$2:$A$255,Cambi!$A$2:$A$255) | H38: =IF(C38="","",C38/F38) | I38: =IF(D38="","",D38/F38) | J38: =J37+N(H38)-N(I38) | K38: =A39-A38 | L38: =K38*J38
A39: 45949 | C39: 600 | E39: =E38+N(C39)-N(D39) | F39: =LOOKUP(A39,Cambi!$A$2:$A$255,Cambi!$B$2:$B$255) | G39: =LOOKUP(A39,Cambi!$A$2:$A$255,Cambi!$A$2:$A$255) | H39: =IF(C39="","",C39/F39) | I39: =IF(D39="","",D39/F39) | J39: =J38+N(H39)-N(I39) | K39: =A40-A39 | L39: =K39*J39
A40: 45965 | C40: 1000 | E40: =E39+N(C40)-N(D40) | F40: =LOOKUP(A40,Cambi!$A$2:$A$255,Cambi!$B$2:$B$255) | G40: =LOOKUP(A40,Cambi!$A$2:$A$255,Cambi!$A$2:$A$255) | H40: =IF(C40="","",C40/F40) | I40: =IF(D40="","",D40/F40) | J40: =J39+N(H40)-N(I40) | K40: =A41-A40 | L40: =K40*J40
...

Sheet Cambi
A1: data | B1: cambio USD per 1 EUR | C1: fonte
A2: 45649 | B2: 1.0393 | C2: Banca d'Italia - tassi di cambio (ex UIC)
A3: 45650 | B3: 1.0395 | C3: Banca d'Italia - tassi di cambio (ex UIC)
A4: 45653 | B4: 1.0435 | C4: Banca d'Italia - tassi di cambio (ex UIC)
A5: 45656 | B5: 1.0444 | C5: Banca d'Italia - tassi di cambio (ex UIC)
A6: 45657 | B6: 1.0389 | C6: Banca d'Italia - tassi di cambio (ex UIC)
A7: 45659 | B7: 1.0321 | C7: Banca d'Italia - tassi di cambio (ex UIC)
A8: 45660 | B8: 1.0299 | C8: Banca d'Italia - tassi di cambio (ex UIC)
A9: 45663 | B9: 1.0426 | C9: Banca d'Italia - tassi di cambio (ex UIC)
A10: 45664 | B10: 1.0393 | C10: Banca d'Italia - tassi di cambio (ex UIC)
A11: 45665 | B11: 1.0286 | C11: Banca d'Italia - tassi di cambio (ex UIC)
A12: 45666 | B12: 1.0305 | C12: Banca d'Italia - tassi di cambio (ex UIC)
A13: 45667 | B13: 1.0304 | C13: Banca d'Italia - tassi di cambio (ex UIC)
... A255: 46010 | B255: 1.1712 | C255: Banca d'Italia - tassi di cambio (ex UIC)

Sheet Medie mensili
A1: anno | B1: mese | C1: cambio medio USD per 1 EUR | D1: fonte
A2: 2024 | B2: 12 | C2: 1.0479 | D2: Medie mensili Banca d'Italia = provvedimenti Agenzia delle Entrate
A3: 2025 | B3: 1 | C3: 1.0354 | D3: Medie mensili Banca d'Italia = provvedimenti Agenzia delle Entrate
A4: 2025 | B4: 12 | C4: 1.1709 | D4: Medie mensili Banca d'Italia = provvedimenti Agenzia delle Entrate
